<?xml version="1.0" ?>
<!-- =================================================================================== -->
<!-- |    This document was autogenerated by xacro from /home/jerry/RosWs/allinone_ws/src/xrrover/xrrover_description/urdf/xrrover.urdf.xacro | -->
<!-- |    EDITING THIS FILE BY HAND IS NOT RECOMMENDED                                 | -->
<!-- =================================================================================== -->
<robot name="rover">
  <!-- in kg-->
  <!-- BASE FOOTPRINT -->
  <link name="base_footprint">
    <visual>
      <origin rpy="0 0 0" xyz="0 0 0"/>
      <geometry>
        <box size="0.001 0.001 0.001"/>
      </geometry>
    </visual>
  </link>
  <joint name="rover_base_footprint_joint" type="fixed">
    <origin rpy="0 0 0" xyz="0 0 0.0441"/>
    <!-- 0.0441 = 0.0762/2 + 0.006(6mm raise the base to allow room for the wheels to move down) -->
    <parent link="base_footprint"/>
    <child link="base_link"/>
  </joint>
  <!-- BASE_LINK -->
  <!-- consists of three link and two fixed joint -->
  <link name="base_link">
    <inertial>
      <mass value="125.0"/>
      <origin xyz="0 0 0"/>
      <inertia ixx="1.391" ixy="0.004" ixz="0.0" iyy="6.853" iyz="0.0" izz="6.125"/>
    </inertial>
    <visual>
      <origin rpy="0 0 0" xyz="0 0 0"/>
      <geometry>
        <box size="0.1375 0.22 0.085"/>
        <!-- base's x(0.29) - two wheel radius(0.0762*2) = 0.1376 => 0.1375 -->
      </geometry>
      <material name="darkgrey">
        <color rgba="0.1 0.1 0.1 1"/>
      </material>
    </visual>
    <collision>
      <!-- base link's collision only define here -->
      <origin rpy="0 0 0 " xyz="0 0 0"/>
      <geometry>
        <box size="0.29 0.22 0.085"/>
      </geometry>
    </collision>
  </link>
  <joint name="base_link_attach_joint" type="fixed">
    <parent link="base_link"/>
    <child link="base_link_attach"/>
  </joint>
  <link name="base_link_attach">
    <visual>
      <origin rpy="0 0 0" xyz="0 0 0"/>
      <geometry>
        <box size="0.29 0.12 0.085"/>
      </geometry>
      <material name="darkgrey">
        <color rgba="0.1 0.1 0.1 1"/>
      </material>
    </visual>
  </link>
  <joint name="base_link_attach_joint2" type="fixed">
    <parent link="base_link"/>
    <child link="base_link_attach2"/>
  </joint>
  <link name="base_link_attach2">
    <visual>
      <origin rpy="0 0 0" xyz="0 0 0.0406"/>
      <geometry>
        <box size="0.29 0.22 0.005"/>
      </geometry>
      <material name="darkgrey">
        <color rgba="0.1 0.1 0.1 1"/>
      </material>
    </visual>
  </link>
  <joint name="rover_front_right_wheel_joint" type="continuous">
    <parent link="base_link"/>
    <child link="rover_front_right_wheel_link"/>
    <origin rpy="0 0 0" xyz="0.1069 -0.09 -0.0061"/>
    <axis rpy="0 0 0" xyz="0 1 0"/>
    <limit effort="10" velocity="10"/>
    <joint_properties damping="0.0" friction="0.0"/>
  </joint>
  <link name="rover_front_right_wheel_link">
    <visual>
      <origin rpy="0 0 0" xyz="0 0 0"/>
      <geometry>
        <mesh filename="package://xrrover_description/meshes/wheels/rover_wheel_2.dae"/>
      </geometry>
    </visual>
    <collision>
      <origin rpy="1.5707963267948966 0 0" xyz="0 0 0"/>
      <geometry>
        <cylinder length="0.04" radius="0.0381"/>
      </geometry>
    </collision>
    <inertial>
      <mass value="6.5"/>
      <origin xyz="0 0 0"/>
      <inertia ixx="0.003225532916666667" ixy="0" ixz="0" iyy="0.0047177325" iyz="0" izz="0.003225532916666667"/>
    </inertial>
  </link>
  <!-- Transmission is important to link the joints and the controller (see summit_xl_control/config/summit_xl_control.yaml)-->
  <transmission name="rover_front_right_wheel_joint_trans">
    <type>transmission_interface/SimpleTransmission</type>
    <joint name="rover_front_right_wheel_joint">
      <hardwareInterface>hardware_interface/VelocityJointInterface</hardwareInterface>
    </joint>
    <actuator name="rover_front_right_wheel_joint_motor">
      <mechanicalReduction>1</mechanicalReduction>
    </actuator>
  </transmission>
  <gazebo reference="rover_front_right_wheel_link">
    <mu1 value="1.0"/>
    <mu2 value="1.0"/>
    <kp value="10000000.0"/>
    <kd value="1.0"/>
    <fdir1 value="1 0 0"/>
    <turnGravityOff>false</turnGravityOff>
  </gazebo>
  <joint name="rover_front_left_wheel_joint" type="continuous">
    <parent link="base_link"/>
    <child link="rover_front_left_wheel_link"/>
    <origin rpy="0 0 0" xyz="0.1069 0.09 -0.0061"/>
    <axis rpy="0 0 0" xyz="0 1 0"/>
    <limit effort="10" velocity="10"/>
    <joint_properties damping="0.0" friction="0.0"/>
  </joint>
  <link name="rover_front_left_wheel_link">
    <visual>
      <origin rpy="0 0 0" xyz="0 0 0"/>
      <geometry>
        <mesh filename="package://xrrover_description/meshes/wheels/rover_wheel_1.dae"/>
      </geometry>
    </visual>
    <collision>
      <origin rpy="1.5707963267948966 0 0" xyz="0 0 0"/>
      <geometry>
        <cylinder length="0.04" radius="0.0381"/>
      </geometry>
    </collision>
    <inertial>
      <mass value="6.5"/>
      <origin xyz="0 0 0"/>
      <inertia ixx="0.003225532916666667" ixy="0" ixz="0" iyy="0.0047177325" iyz="0" izz="0.003225532916666667"/>
    </inertial>
  </link>
  <!-- Transmission is important to link the joints and the controller (see summit_xl_control/config/summit_xl_control.yaml)-->
  <transmission name="rover_front_left_wheel_joint_trans">
    <type>transmission_interface/SimpleTransmission</type>
    <joint name="rover_front_left_wheel_joint">
      <hardwareInterface>hardware_interface/VelocityJointInterface</hardwareInterface>
    </joint>
    <actuator name="rover_front_left_wheel_joint_motor">
      <mechanicalReduction>1</mechanicalReduction>
    </actuator>
  </transmission>
  <gazebo reference="rover_front_left_wheel_link">
    <mu1 value="1.0"/>
    <mu2 value="1.0"/>
    <kp value="10000000.0"/>
    <kd value="1.0"/>
    <fdir1 value="1 0 0"/>
    <turnGravityOff>false</turnGravityOff>
  </gazebo>
  <joint name="rover_rear_left_wheel_joint" type="continuous">
    <parent link="base_link"/>
    <child link="rover_rear_left_wheel_link"/>
    <origin rpy="0 0 0" xyz="-0.1069 0.09 -0.0061"/>
    <axis rpy="0 0 0" xyz="0 1 0"/>
    <limit effort="10" velocity="10"/>
    <joint_properties damping="0.0" friction="0.0"/>
  </joint>
  <link name="rover_rear_left_wheel_link">
    <visual>
      <origin rpy="0 0 0" xyz="0 0 0"/>
      <geometry>
        <mesh filename="package://xrrover_description/meshes/wheels/rover_wheel_1.dae"/>
      </geometry>
    </visual>
    <collision>
      <origin rpy="1.5707963267948966 0 0" xyz="0 0 0"/>
      <geometry>
        <cylinder length="0.04" radius="0.0381"/>
      </geometry>
    </collision>
    <inertial>
      <mass value="6.5"/>
      <origin xyz="0 0 0"/>
      <inertia ixx="0.003225532916666667" ixy="0" ixz="0" iyy="0.0047177325" iyz="0" izz="0.003225532916666667"/>
    </inertial>
  </link>
  <!-- Transmission is important to link the joints and the controller (see summit_xl_control/config/summit_xl_control.yaml)-->
  <transmission name="rover_rear_left_wheel_joint_trans">
    <type>transmission_interface/SimpleTransmission</type>
    <joint name="rover_rear_left_wheel_joint">
      <hardwareInterface>hardware_interface/VelocityJointInterface</hardwareInterface>
    </joint>
    <actuator name="rover_rear_left_wheel_joint_motor">
      <mechanicalReduction>1</mechanicalReduction>
    </actuator>
  </transmission>
  <gazebo reference="rover_rear_left_wheel_link">
    <mu1 value="1.0"/>
    <mu2 value="1.0"/>
    <kp value="10000000.0"/>
    <kd value="1.0"/>
    <fdir1 value="1 0 0"/>
    <turnGravityOff>false</turnGravityOff>
  </gazebo>
  <joint name="rover_rear_right_wheel_joint" type="continuous">
    <parent link="base_link"/>
    <child link="rover_rear_right_wheel_link"/>
    <origin rpy="0 0 0" xyz="-0.1069 -0.09 -0.0061"/>
    <axis rpy="0 0 0" xyz="0 1 0"/>
    <limit effort="10" velocity="10"/>
    <joint_properties damping="0.0" friction="0.0"/>
  </joint>
  <link name="rover_rear_right_wheel_link">
    <visual>
      <origin rpy="0 0 0" xyz="0 0 0"/>
      <geometry>
        <mesh filename="package://xrrover_description/meshes/wheels/rover_wheel_2.dae"/>
      </geometry>
    </visual>
    <collision>
      <origin rpy="1.5707963267948966 0 0" xyz="0 0 0"/>
      <geometry>
        <cylinder length="0.04" radius="0.0381"/>
      </geometry>
    </collision>
    <inertial>
      <mass value="6.5"/>
      <origin xyz="0 0 0"/>
      <inertia ixx="0.003225532916666667" ixy="0" ixz="0" iyy="0.0047177325" iyz="0" izz="0.003225532916666667"/>
    </inertial>
  </link>
  <!-- Transmission is important to link the joints and the controller (see summit_xl_control/config/summit_xl_control.yaml)-->
  <transmission name="rover_rear_right_wheel_joint_trans">
    <type>transmission_interface/SimpleTransmission</type>
    <joint name="rover_rear_right_wheel_joint">
      <hardwareInterface>hardware_interface/VelocityJointInterface</hardwareInterface>
    </joint>
    <actuator name="rover_rear_right_wheel_joint_motor">
      <mechanicalReduction>1</mechanicalReduction>
    </actuator>
  </transmission>
  <gazebo reference="rover_rear_right_wheel_link">
    <mu1 value="1.0"/>
    <mu2 value="1.0"/>
    <kp value="10000000.0"/>
    <kd value="1.0"/>
    <fdir1 value="1 0 0"/>
    <turnGravityOff>false</turnGravityOff>
  </gazebo>
  <joint name="joint_sensor_laser" type="fixed">
    <origin rpy="0 0 0" xyz="0.05 0 0.0691"/>
    <!-- 0.0691 = 0.0381 + 0.05/2 + 0.006 -->
    <!-- 0.0691 = 0.0381 + cylinder_length/2 + base_link_to_footprint's_0.006 -->
    <parent link="base_link"/>
    <child link="base_scan"/>
  </joint>
  <link name="base_scan">
    <inertial>
      <origin rpy="0 0 0" xyz="0 0 0"/>
      <mass value="1"/>
      <inertia ixx="0.0014583333333333334" ixy="0" ixz="0" iyy="0.0014583333333333334" iyz="0" izz="0.0012500000000000002"/>
    </inertial>
    <visual>
      <origin rpy="0 0 0" xyz="0 0 0"/>
      <geometry>
        <cylinder length="0.05" radius="0.05"/>
      </geometry>
      <material name="white">
        <color rgba="1.0 1.0 1.0 1.0"/>
      </material>
    </visual>
    <collision>
      <origin rpy="0 0 0" xyz="0 0 0"/>
      <geometry>
        <cylinder length="0.05" radius="0.05"/>
      </geometry>
    </collision>
  </link>
  <gazebo>
    <plugin filename="libgazebo_ros_planar_move.so" name="mecanum_controller">
      <commandTopic>cmd_vel</commandTopic>
      <odometryTopic>odom</odometryTopic>
      <odometryFrame>odom</odometryFrame>
      <odometryRate>20.0</odometryRate>
      <robotBaseFrame>base_footprint</robotBaseFrame>
    </plugin>
  </gazebo>
  <gazebo reference="base_scan">
    <material>Gazebo/Red</material>
  </gazebo>
  <gazebo reference="base_scan">
    <sensor name="head_hokuyo_sensor" type="ray">
      <pose>0 0 0 0 0 0</pose>
      <visualize>false</visualize>
      <update_rate>20</update_rate>
      <ray>
        <scan>
          <horizontal>
            <samples>720</samples>
            <resolution>1</resolution>
            <min_angle>-1.570796</min_angle>
            <max_angle>1.570796</max_angle>
          </horizontal>
        </scan>
        <range>
          <min>0.10</min>
          <max>2.0</max>
          <resolution>0.01</resolution>
        </range>
        <noise>
          <type>gaussian</type>
          <mean>0.0</mean>
          <stddev>0.01</stddev>
        </noise>
      </ray>
      <plugin filename="libgazebo_ros_laser.so" name="gazebo_ros_head_hokuyo_controller">
        <topicName>scan</topicName>
        <frameName>base_scan</frameName>
      </plugin>
    </sensor>
  </gazebo>
</robot>
